Workbook

Sheet Cover
E5: Microsoft Corporation
E6: Valuation Model
E9: NASDAQ: MSFT
E11: Prepared by: | F11: Selwyn Rai
E12: Valuation Date: | F12: 46231
E13: Model Version: | F13: Final
E14: Currency: | F14: USD
E17: Assumptions • Three-Statement Model • Supporting Schedules • DCF • Sensitivity Analysis

Sheet Assumptions
B2: Assumptions
B4: Driver | C4: Historical | E4: Forecast
C5: FY2024A | D5: FY2025A | E5: FY2026E | F5: FY2027E | G5: FY2028E | H5: FY2029E | I5: FY2030E
B7: Growth
B8: Revenue Growth (%) | C8: =('Income Statement'!D11-'Income Statement'!C11)/'Income Statement'!C11 -> 0.15669962 | D8: =('Income Statement'!E11-'Income Statement'!D11)/'Income Statement'!D11 -> 0.14932156 | E8: 0.13 | F8: 0.115 | G8: 0.1 | H8: 0.085 | I8: 0.075
B10: Margins
B11: Gross Margin (%) | C11: ='Income Statement'!D19/'Income Statement'!D11 -> 0.69764444 | D11: ='Income Statement'!E19/'Income Statement'!E11 -> 0.68823742 | E11: 0.69 | F11: 0.691 | G11: 0.692 | H11: 0.692 | I11: 0.693
B12: R&D (% Revenue) | C12: ='Income Statement'!D22/'Income Statement'!D11 -> 0.12038903 | D12: ='Income Statement'!E22/'Income Statement'!E11 -> 0.11531854 | E12: 0.115 | F12: 0.114 | G12: 0.113 | H12: 0.112 | I12: 0.111
B13: Sales and Marketing (% Revenue) | C13: ='Income Statement'!D23/'Income Statement'!D11 -> 0.099770726 | D13: ='Income Statement'!E23/'Income Statement'!E11 -> 0.091060754 | E13: 0.09 | F13: 0.089 | G13: 0.088 | H13: 0.088 | I13: 0.087
B14: G&A (% Revenue) | C14: ='Income Statement'!D24/'Income Statement'!D11 -> 0.031041685 | D14: ='Income Statement'!E24/'Income Statement'!E11 -> 0.025638568 | E14: 0.025 | F14: 0.025 | G14: 0.024 | H14: 0.024 | I14: 0.023
B15: Implied Operating Margin (%) | C15: ='Income Statement'!D28/'Income Statement'!D11 -> 0.446443 | D15: ='Income Statement'!E28/'Income Statement'!E11 -> 0.45621956 | E15: ='Income Statement'!F28/'Income Statement'!F11 -> 0.46 | F15: ='Income Statement'!G28/'Income Statement'!G11 -> 0.463 | G15: ='Income Statement'!H28/'Income Statement'!H11 -> 0.467 | H15: ='Income Statement'!I28/'Income Statement'!I11 -> 0.468 | I15: ='Income Statement'!J28/'Income Statement'!J11 -> 0.472
B16: Tax Rate (%) | C16: ='Income Statement'!D34/'Income Statement'!D32 -> 0.18231327 | D16: ='Income Statement'!E34/'Income Statement'!E32 -> 0.17629644 | E16: 0.18 | F16: 0.18 | G16: 0.18 | H16: 0.18 | I16: 0.18
B18: Investment
B19: CapEx (% Revenue) | C19: =ABS('Cash Flow Statement'!D30)/'Income Statement'!D11 -> 0.18144842 | D19: =ABS('Cash Flow Statement'!E30)/'Income Statement'!E11 -> 0.22912851 | E19: 0.21 | F19: 0.2 | G19: 0.19 | H19: 0.18 | I19: 0.17
B20: Depreciation (% Revenue) | C20: ='Cash Flow Statement'!D11/'Income Statement'!D11 -> 0.090922071 | D20: ='Cash Flow Statement'!E11/'Income Statement'!E11 -> 0.12122858 | E20: 0.12 | F20: 0.12 | G20: 0.118 | H20: 0.116 | I20: 0.115
B21: Investment Purchases (% Revenue) | C21: =ABS('Cash Flow Statement'!D32)/'Income Statement'!D11 -> 0.072339488 | D21: =ABS('Cash Flow Statement'!E32)/'Income Statement'!E11 -> 0.10568855 | E21: 0.1 | F21: 0.095 | G21: 0.09 | H21: 0.085 | I21: 0.08
B23: Working Capital
B24: Accounts Receivable (% Revenue) | C24: ='Balance Sheet'!D14/'Income Statement'!D11 -> 0.23222722 | D24: ='Balance Sheet'!E14/'Income Statement'!E11 -> 0.24813292 | E24: 0.25 | F24: 0.25 | G24: 0.248 | H24: 0.245 | I24: 0.24
B25: Inventory (% Revenue) | C25: ='Balance Sheet'!D15/'Income Statement'!D11 -> 0.0050831831 | D25: ='Balance Sheet'!E15/'Income Statement'!E11 -> 0.0033294998 | E25: 0.003 | F25: 0.003 | G25: 0.003 | H25: 0.003 | I25: 0.003
B26: Accounts Payable (% Revenue) | C26: ='Balance Sheet'!D35/'Income Statement'!D11 -> 0.089734908 | D26: ='Balance Sheet'!E35/'Income Statement'!E11 -> 0.098408371 | E26: 0.1 | F26: 0.1 | G26: 0.098 | H26: 0.096 | I26: 0.095
B28: Capital Allocation
B29: Dividend Growth (%) | C29: =(ABS('Cash Flow Statement'!D45)-ABS('Cash Flow Statement'!C45))/ABS('Cash Flow Statement'!C45) -> 0.099545455 | D29: =(ABS('Cash Flow Statement'!E45)-ABS('Cash Flow Statement'!D45))/ABS('Cash Flow Statement'!D45) -> 0.10615038 | E29: 0.1 | F29: 0.1 | G29: 0.095 | H29: 0.09 | I29: 0.085

Sheet Income Statement
B2: Income Statement
B4: ($ in millions, except per share data) | C4: Historical | F4: Forecast
C5: FY2023A | D5: FY2024A | E5: FY2025A | F5: FY2026E | G5: FY2027E | H5: FY2028E | I5: FY2029E | J5: FY2030E
B7: Revenue:
B8: Product | C8: 64699 | D8: 64773 | E8: 63946 | F8: =E8*(1+Assumptions!E8) -> 72258.98 | G8: =F8*(1+Assumptions!F8) -> 80568.763 | H8: =G8*(1+Assumptions!G8) -> 88625.639 | I8: =H8*(1+Assumptions!H8) -> 96158.818 | J8: =I8*(1+Assumptions!I8) -> 103370.73
B9: Service and Other | C9: 147216 | D9: 180349 | E9: 217778 | F9: =E9*(1+Assumptions!E8) -> 246089.14 | G9: =F9*(1+Assumptions!F8) -> 274389.39 | H9: =G9*(1+Assumptions!G8) -> 301828.33 | I9: =H9*(1+Assumptions!H8) -> 327483.74 | J9: =I9*(1+Assumptions!I8) -> 352045.02
B11: Total Revenue | C11: =SUM(C8:C9) -> 211915 | D11: =SUM(D8:D9) -> 245122 | E11: =SUM(E8:E9) -> 281724 | F11: =SUM(F8:F9) -> 318348.12 | G11: =SUM(G8:G9) -> 354958.15 | H11: =SUM(H8:H9) -> 390453.97 | I11: =SUM(I8:I9) -> 423642.56 | J11: =SUM(J8:J9) -> 455415.75
B13: Cost of Revenue:
B14: Product | C14: 17804 | D14: 15272 | E14: 13501
B15: Service and Other | C15: 48059 | D15: 58842 | E15: 74330
B17: Total Cost of Revenue | C17: =SUM(C14:C15) -> 65863 | D17: =SUM(D14:D15) -> 74114 | E17: =SUM(E14:E15) -> 87831 | F17: =F11-F19 -> 98687.917 | G17: =G11-G19 -> 109682.07 | H17: =H11-H19 -> 120259.82 | I17: =I11-I19 -> 130481.91 | J17: =J11-J19 -> 139812.63
B19: Gross Profit | C19: =C11-C17 -> 146052 | D19: =D11-D17 -> 171008 | E19: =E11-E17 -> 193893 | F19: =F11*Assumptions!E11 -> 219660.2 | G19: =G11*Assumptions!F11 -> 245276.08 | H19: =H11*Assumptions!G11 -> 270194.15 | I19: =I11*Assumptions!H11 -> 293160.65 | J19: =J11*Assumptions!I11 -> 315603.11
B21: Operating Expenses:
B22: Research and Development | C22: 27195 | D22: 29510 | E22: 32488 | F22: =F11*Assumptions!E12 -> 36610.034 | G22: =G11*Assumptions!F12 -> 40465.23 | H22: =H11*Assumptions!G12 -> 44121.299 | I22: =I11*Assumptions!H12 -> 47447.966 | J22: =J11*Assumptions!I12 -> 50551.148
B23: Sales and Marketing | C23: 22759 | D23: 24456 | E23: 25654 | F23: =F11*Assumptions!E13 -> 28651.331 | G23: =G11*Assumptions!F13 -> 31591.276 | H23: =H11*Assumptions!G13 -> 34359.949 | I23: =I11*Assumptions!H13 -> 37280.545 | J23: =J11*Assumptions!I13 -> 39621.17
B24: General and Administrative | C24: 7575 | D24: 7609 | E24: 7223 | F24: =F11*Assumptions!E14 -> 7958.703 | G24: =G11*Assumptions!F14 -> 8873.9538 | H24: =H11*Assumptions!G14 -> 9370.8953 | I24: =I11*Assumptions!H14 -> 10167.421 | J24: =J11*Assumptions!I14 -> 10474.562
B26: Total Operating Expenses | C26: =SUM(C22:C24) -> 57529 | D26: =SUM(D22:D24) -> 61575 | E26: =SUM(E22:E24) -> 65365 | F26: =SUM(F22:F24) -> 73220.068 | G26: =SUM(G22:G24) -> 80930.459 | H26: =SUM(H22:H24) -> 87852.143 | I26: =SUM(I22:I24) -> 94895.933 | J26: =SUM(J22:J24) -> 100646.88
B28: Operating Income | C28: =C19-C26 -> 88523 | D28: =D19-D26 -> 109433 | E28: =E19-E26 -> 128528 | F28: =F19-F26 -> 146440.14 | G28: =G19-G26 -> 164345.63 | H28: =H19-H26 -> 182342 | I28: =I19-I26 -> 198264.72 | J28: =J19-J26 -> 214956.23
B30: Other Income (expense), Net | C30: 788 | D30: -1646 | E30: -4901 | F30: =E30 -> -4901 | G30: =F30 -> -4901 | H30: =G30 -> -4901 | I30: =H30 -> -4901 | J30: =I30 -> -4901
B32: Income before taxes | C32: =SUM(C28:C30) -> 89311 | D32: =SUM(D28:D30) -> 107787 | E32: =SUM(E28:E30) -> 123627 | F32: =SUM(F28:F30) -> 141539.14 | G32: =SUM(G28:G30) -> 159444.63 | H32: =SUM(H28:H30) -> 177441 | I32: =SUM(I28:I30) -> 193363.72 | J32: =SUM(J28:J30) -> 210055.23
B34: Income Tax Expense | C34: 16950 | D34: 19651 | E34: 21795 | F34: =F32*Assumptions!E16 -> 25477.044 | G34: =G32*Assumptions!F16 -> 28700.033 | H34: =H32*Assumptions!G16 -> 31939.381 | I34: =I32*Assumptions!H16 -> 34805.469 | J34: =J32*Assumptions!I16 -> 37809.942
B36: Net Income | C36: =C32-C34 -> 72361 | D36: =D32-D34 -> 88136 | E36: =E32-E34 -> 101832 | F36: =F32-F34 -> 116062.09 | G36: =G32-G34 -> 130744.59 | H36: =H32-H34 -> 145501.62 | I36: =I32-I34 -> 158558.25 | J36: =J32-J34 -> 172245.29
B38: Earnings Per Share:
B39: Basic | C39: =C36/C43 -> 9.7181037 | D39: =D36/D43 -> 11.860584 | E39: =E36/E43 -> 13.68158 | F39: =F36/F43 -> 15.593456 | G39: =G36/G43 -> 17.566115 | H39: =H36/H43 -> 19.548787 | I39: =I36/I43 -> 21.303002 | J39: =J36/J43 -> 23.141917
B40: Diluted | C40: =C36/C44 -> 9.684288 | D40: =D36/D44 -> 11.800241 | E40: =E36/E44 -> 13.62848 | F40: =F36/F44 -> 15.532935 | G40: =G36/G44 -> 17.497938 | H40: =H36/H44 -> 19.472915 | I40: =I36/I44 -> 21.220322 | J40: =J36/J44 -> 23.0521
B42: Weighted Average Shares Outstanding:
B43: Basic | C43: 7446 | D43: 7431 | E43: 7443 | F43: =E43 -> 7443 | G43: =F43 -> 7443 | H43: =G43 -> 7443 | I43: =H43 -> 7443 | J43: =I43 -> 7443
B44: Diluted | C44: 7472 | D44: 7469 | E44: 7472 | F44: =E44 -> 7472 | G44: =F44 -> 7472 | H44: =G44 -> 7472 | I44: =H44 -> 7472 | J44: =I44 -> 7472

Sheet Balance Sheet
B2: Balance Sheet
B4: ($ in millions) | C4: Historical | F4: Forecast
C5: FY2023A | D5: FY2024A | E5: FY2025A | F5: FY2026E | G5: FY2027E | H5: FY2028E | I5: FY2029E | J5: FY2030E
B7: Assets
B9: Current Assets:
B10: Cash and Cash Equivalents | C10: ='Cash Flow Statement'!C56 -> 34704 | D10: ='Cash Flow Statement'!D56 -> 18315 | E10: ='Cash Flow Statement'!E56 -> 30242 | F10: ='Cash Flow Statement'!F56 -> 53739.486 | G10: ='Cash Flow Statement'!G56 -> 87625.846 | H10: ='Cash Flow Statement'!H56 -> 132535.62 | I10: ='Cash Flow Statement'!I56 -> 188537.8 | J10: ='Cash Flow Statement'!J56 -> 258558.76
B11: Short-term Investments | C11: 76558 | D11: 57228 | E11: 64323 | F11: =E11-'Cash Flow Statement'!F32 -> 96157.812 | G11: =F11-'Cash Flow Statement'!G32 -> 129878.84 | H11: =G11-'Cash Flow Statement'!H32 -> 165019.69 | I11: =H11-'Cash Flow Statement'!I32 -> 201029.31 | J11: =I11-'Cash Flow Statement'!J32 -> 237462.57
B13: Total Cash and Short-Term Investments | C13: =SUM(C10:C11) -> 111262 | D13: =SUM(D10:D11) -> 75543 | E13: =SUM(E10:E11) -> 94565 | F13: =SUM(F10:F11) -> 149897.3 | G13: =SUM(G10:G11) -> 217504.68 | H13: =SUM(H10:H11) -> 297555.31 | I13: =SUM(I10:I11) -> 389567.11 | J13: =SUM(J10:J11) -> 496021.33
B14: Accounts Receivable, Net | C14: 48688 | D14: 56924 | E14: 69905 | F14: ='Income Statement'!F11*Assumptions!E24 -> 79587.03 | G14: ='Income Statement'!G11*Assumptions!F24 -> 88739.538 | H14: ='Income Statement'!H11*Assumptions!G24 -> 96832.584 | I14: ='Income Statement'!I11*Assumptions!H24 -> 103792.43 | J14: ='Income Statement'!J11*Assumptions!I24 -> 109299.78
B15: Inventories | C15: 2500 | D15: 1246 | E15: 938 | F15: ='Income Statement'!F11*Assumptions!E25 -> 955.04436 | G15: ='Income Statement'!G11*Assumptions!F25 -> 1064.8745 | H15: ='Income Statement'!H11*Assumptions!G25 -> 1171.3619 | I15: ='Income Statement'!I11*Assumptions!H25 -> 1270.9277 | J15: ='Income Statement'!J11*Assumptions!I25 -> 1366.2472
B16: Other Current Assets | C16: 21807 | D16: 26021 | E16: 25723 | F16: =E16 -> 25723 | G16: =F16 -> 25723 | H16: =G16 -> 25723 | I16: =H16 -> 25723 | J16: =I16 -> 25723
B18: Total Current Assets | C18: =SUM(C13:C16) -> 184257 | D18: =SUM(D13:D16) -> 159734 | E18: =SUM(E13:E16) -> 191131 | F18: =SUM(F13:F16) -> 256162.37 | G18: =SUM(G13:G16) -> 333032.1 | H18: =SUM(H13:H16) -> 421282.26 | I18: =SUM(I13:I16) -> 520353.46 | J18: =SUM(J13:J16) -> 632410.36
B20: Non-Current Assets:
B21: Property and Equipment, Net | C21: 95641 | D21: 135591 | E21: 204966 | F21: =E21-'Cash Flow Statement'!F30-'Cash Flow Statement'!F11 -> 233617.33 | G21: =F21-'Cash Flow Statement'!G30-'Cash Flow Statement'!G11 -> 262013.98 | H21: =G21-'Cash Flow Statement'!H30-'Cash Flow Statement'!H11 -> 290126.67 | I21: =H21-'Cash Flow Statement'!I30-'Cash Flow Statement'!I11 -> 317239.79 | J21: =I21-'Cash Flow Statement'!J30-'Cash Flow Statement'!J11 -> 342287.66
B22: Operating Lease ROU Assets | C22: 14346 | D22: 18961 | E22: 24823 | F22: =E22 -> 24823 | G22: =F22 -> 24823 | H22: =G22 -> 24823 | I22: =H22 -> 24823 | J22: =I22 -> 24823
B23: Equity and Other Investments | C23: 9879 | D23: 14600 | E23: 15405 | F23: =E23 -> 15405 | G23: =F23 -> 15405 | H23: =G23 -> 15405 | I23: =H23 -> 15405 | J23: =I23 -> 15405
B24: Goodwill | C24: 67886 | D24: 119220 | E24: 119509 | F24: =E24 -> 119509 | G24: =F24 -> 119509 | H24: =G24 -> 119509 | I24: =H24 -> 119509 | J24: =I24 -> 119509
B25: Intangible Assets, Net | C25: 9366 | D25: 27597 | E25: 22604 | F25: =E25 -> 22604 | G25: =F25 -> 22604 | H25: =G25 -> 22604 | I25: =H25 -> 22604 | J25: =I25 -> 22604
B26: Other Long-Term Assets | C26: 30601 | D26: 36460 | E26: 40565 | F26: =E26 -> 40565 | G26: =F26 -> 40565 | H26: =G26 -> 40565 | I26: =H26 -> 40565 | J26: =I26 -> 40565
B28: Total Non-Current Assets | C28: =SUM(C21:C26) -> 227719 | D28: =SUM(D21:D26) -> 352429 | E28: =SUM(E21:E26) -> 427872 | F28: =SUM(F21:F26) -> 456523.33 | G28: =SUM(G21:G26) -> 484919.98 | H28: =SUM(H21:H26) -> 513032.67 | I28: =SUM(I21:I26) -> 540145.79 | J28: =SUM(J21:J26) -> 565193.66
B30: Total Assets | C30: =SUM(C18+C28) -> 411976 | D30: =SUM(D18+D28) -> 512163 | E30: =SUM(E18+E28) -> 619003 | F30: =SUM(F18+F28) -> 712685.7 | G30: =SUM(G18+G28) -> 817952.08 | H30: =SUM(H18+H28) -> 934314.93 | I30: =SUM(I18+I28) -> 1060499.3 | J30: =SUM(J18+J28) -> 1197604
B32: Liabilities and Stockholders' Equity
B34: Current Liabilities:
B35: Accounts Payable | C35: 18095 | D35: 21996 | E35: 27724 | F35: ='Income Statement'!F11*Assumptions!E26 -> 31834.812 | G35: ='Income Statement'!G11*Assumptions!F26 -> 35495.815 | H35: ='Income Statement'!H11*Assumptions!G26 -> 38264.489 | I35: ='Income Statement'!I11*Assumptions!H26 -> 40669.685 | J35: ='Income Statement'!J11*Assumptions!I26 -> 43264.496
B36: Short-Term Debt | C36: 0 | D36: 6693 | E36: 0 | F36: =E36 -> 0 | G36: =F36 -> 0 | H36: =G36 -> 0 | I36: =H36 -> 0 | J36: =I36 -> 0
B37: Current Portion of Long-Term Debt | C37: 5247 | D37: 2249 | E37: 2999 | F37: =E37 -> 2999 | G37: =F37 -> 2999 | H37: =G37 -> 2999 | I37: =H37 -> 2999 | J37: =I37 -> 2999
B38: Accrued Compensation | C38: 11009 | D38: 12564 | E38: 13709 | F38: =E38 -> 13709 | G38: =F38 -> 13709 | H38: =G38 -> 13709 | I38: =H38 -> 13709 | J38: =I38 -> 13709
B39: Short-Term Income Taxes | C39: 4152 | D39: 5017 | E39: 7211 | F39: =E39 -> 7211 | G39: =F39 -> 7211 | H39: =G39 -> 7211 | I39: =H39 -> 7211 | J39: =I39 -> 7211
B40: Short-Term Unearned Revenue | C40: 50901 | D40: 57582 | E40: 64555 | F40: =E40 -> 64555 | G40: =F40 -> 64555 | H40: =G40 -> 64555 | I40: =H40 -> 64555 | J40: =I40 -> 64555
B41: Other Current Liabilities | C41: 14745 | D41: 19185 | E41: 25020 | F41: =E41 -> 25020 | G41: =F41 -> 25020 | H41: =G41 -> 25020 | I41: =H41 -> 25020 | J41: =I41 -> 25020
B43: Total Current Liabilities: | C43: =SUM(C35:C41) -> 104149 | D43: =SUM(D35:D41) -> 125286 | E43: =SUM(E35:E41) -> 141218 | F43: =SUM(F35:F41) -> 145328.81 | G43: =SUM(G35:G41) -> 148989.82 | H43: =SUM(H35:H41) -> 151758.49 | I43: =SUM(I35:I41) -> 154163.69 | J43: =SUM(J35:J41) -> 156758.5
B45: Non-Current Liabilities:
B46: Long-Term Debt | C46: 41990 | D46: 42688 | E46: 40152 | F46: =E46 -> 40152 | G46: =F46 -> 40152 | H46: =G46 -> 40152 | I46: =H46 -> 40152 | J46: =I46 -> 40152
B47: Long-Term Income Taxes | C47: 25560 | D47: 27931 | E47: 25986 | F47: =E47 -> 25986 | G47: =F47 -> 25986 | H47: =G47 -> 25986 | I47: =H47 -> 25986 | J47: =I47 -> 25986
B48: Long-Term Unearned Revenue | C48: 2912 | D48: 2602 | E48: 2710 | F48: =E48 -> 2710 | G48: =F48 -> 2710 | H48: =G48 -> 2710 | I48: =H48 -> 2710 | J48: =I48 -> 2710
B49: Deferred Income Taxes | C49: 433 | D49: 2618 | E49: 2835 | F49: =E49 -> 2835 | G49: =F49 -> 2835 | H49: =G49 -> 2835 | I49: =H49 -> 2835 | J49: =I49 -> 2835
B50: Operating Lease Liabilities | C50: 12728 | D50: 15497 | E50: 17437 | F50: =E50 -> 17437 | G50: =F50 -> 17437 | H50: =G50 -> 17437 | I50: =H50 -> 17437 | J50: =I50 -> 17437
B51: Other Long-term Liabilities | C51: 17981 | D51: 27064 | E51: 45186 | F51: =E51 -> 45186 | G51: =F51 -> 45186 | H51: =G51 -> 45186 | I51: =H51 -> 45186 | J51: =I51 -> 45186
B53: Total Non-Current Liabilities | C53: =SUM(C46:C51) -> 101604 | D53: =SUM(D46:D51) -> 118400 | E53: =SUM(E46:E51) -> 134306 | F53: =SUM(F46:F51) -> 134306 | G53: =SUM(G46:G51) -> 134306 | H53: =SUM(H46:H51) -> 134306 | I53: =SUM(I46:I51) -> 134306 | J53: =SUM(J46:J51) -> 134306
B55: Total Liabilities | C55: =SUM(C43+C53) -> 205753 | D55: =SUM(D43+D53) -> 243686 | E55: =SUM(E43+E53) -> 275524 | F55: =SUM(F43+F53) -> 279634.81 | G55: =SUM(G43+G53) -> 283295.82 | H55: =SUM(H43+H53) -> 286064.49 | I55: =SUM(I43+I53) -> 288469.69 | J55: =SUM(J43+J53) -> 291064.5
...

Sheet Cash Flow Statement
B2: Cash Flow Statement
B4: ($ in millions) | C4: Historical | F4: Forecast
C5: FY2023A | D5: FY2024A | E5: FY2025A | F5: FY2026E | G5: FY2027E | H5: FY2028E | I5: FY2029E | J5: FY2030E
B6: Net Income | C6: ='Income Statement'!C36 -> 72361 | D6: ='Income Statement'!D36 -> 88136 | E6: ='Income Statement'!E36 -> 101832 | F6: ='Income Statement'!F36 -> 116062.09 | G6: ='Income Statement'!G36 -> 130744.59 | H6: ='Income Statement'!H36 -> 145501.62 | I6: ='Income Statement'!I36 -> 158558.25 | J6: ='Income Statement'!J36 -> 172245.29
B8: Operating Activities:
B10: Adjustments:
B11: Depreciation, Amortization, and other | C11: 13861 | D11: 22287 | E11: 34153 | F11: ='Income Statement'!F11*Assumptions!E20 -> 38201.774 | G11: ='Income Statement'!G11*Assumptions!F20 -> 42594.978 | H11: ='Income Statement'!H11*Assumptions!G20 -> 46073.568 | I11: ='Income Statement'!I11*Assumptions!H20 -> 49142.537 | J11: ='Income Statement'!J11*Assumptions!I20 -> 52372.811
B12: Stock-based Compensation Expense | C12: 9611 | D12: 10734 | E12: 11974 | F12: 0 | G12: =F12 -> 0 | H12: =G12 -> 0 | I12: =H12 -> 0 | J12: =I12 -> 0
B13: Investment and Derivatives Gains/Losses | C13: 196 | D13: 305 | E13: 609 | F13: 0 | G13: =F13 -> 0 | H13: =G13 -> 0 | I13: =H13 -> 0 | J13: =I13 -> 0
B14: Deferred Income Taxes | C14: -6059 | D14: -4738 | E14: -7056 | F14: 0 | G14: =F14 -> 0 | H14: =G14 -> 0 | I14: =H14 -> 0 | J14: =I14 -> 0
B16: Changes in Operating Assets and Liabilities:
B17: Accounts Receivable | C17: -4087 | D17: -7191 | E17: -10581 | F17: =-('Balance Sheet'!F14-'Balance Sheet'!E14) -> -9682.03 | G17: =-('Balance Sheet'!G14-'Balance Sheet'!F14) -> -9152.5084 | H17: =-('Balance Sheet'!H14-'Balance Sheet'!G14) -> -8093.0459 | I17: =-('Balance Sheet'!I14-'Balance Sheet'!H14) -> -6959.842 | J17: =-('Balance Sheet'!J14-'Balance Sheet'!I14) -> -5507.3532
B18: Inventories | C18: 1242 | D18: 1284 | E18: 309 | F18: =-('Balance Sheet'!F15-'Balance Sheet'!E15) -> -17.04436 | G18: =-('Balance Sheet'!G15-'Balance Sheet'!F15) -> -109.8301 | H18: =-('Balance Sheet'!H15-'Balance Sheet'!G15) -> -106.48745 | I18: =-('Balance Sheet'!I15-'Balance Sheet'!H15) -> -99.565762 | J18: =-('Balance Sheet'!J15-'Balance Sheet'!I15) -> -95.319575
B19: Other Current Assets | C19: -1991 | D19: -1648 | E19: -3044 | F19: =-('Balance Sheet'!F16-'Balance Sheet'!E16) -> 0 | G19: =-('Balance Sheet'!G16-'Balance Sheet'!F16) -> 0 | H19: =-('Balance Sheet'!H16-'Balance Sheet'!G16) -> 0 | I19: =-('Balance Sheet'!I16-'Balance Sheet'!H16) -> 0 | J19: =-('Balance Sheet'!J16-'Balance Sheet'!I16) -> 0
B20: Other Long-Term Assets | C20: -2833 | D20: -6817 | E20: -2950 | F20: =-('Balance Sheet'!F26-'Balance Sheet'!E26) -> 0 | G20: =-('Balance Sheet'!G26-'Balance Sheet'!F26) -> 0 | H20: =-('Balance Sheet'!H26-'Balance Sheet'!G26) -> 0 | I20: =-('Balance Sheet'!I26-'Balance Sheet'!H26) -> 0 | J20: =-('Balance Sheet'!J26-'Balance Sheet'!I26) -> 0
B21: Accounts Payable | C21: -2721 | D21: 3545 | E21: 569 | F21: ='Balance Sheet'!F35-'Balance Sheet'!E35 -> 4110.812 | G21: ='Balance Sheet'!G35-'Balance Sheet'!F35 -> 3661.0034 | H21: ='Balance Sheet'!H35-'Balance Sheet'!G35 -> 2768.6736 | I21: ='Balance Sheet'!I35-'Balance Sheet'!H35 -> 2405.1965 | J21: ='Balance Sheet'!J35-'Balance Sheet'!I35 -> 2594.8107
B22: Unearned Revenue | C22: 5535 | D22: 5348 | E22: 5438 | F22: =('Balance Sheet'!F40+'Balance Sheet'!F48)-('Balance Sheet'!E40+'Balance Sheet'!E48) -> 0 | G22: =('Balance Sheet'!G40+'Balance Sheet'!G48)-('Balance Sheet'!F40+'Balance Sheet'!F48) -> 0 | H22: =('Balance Sheet'!H40+'Balance Sheet'!H48)-('Balance Sheet'!G40+'Balance Sheet'!G48) -> 0 | I22: =('Balance Sheet'!I40+'Balance Sheet'!I48)-('Balance Sheet'!H40+'Balance Sheet'!H48) -> 0 | J22: =('Balance Sheet'!J40+'Balance Sheet'!J48)-('Balance Sheet'!I40+'Balance Sheet'!I48) -> 0
B23: Income Taxes | C23: -358 | D23: 1687 | E23: -38 | F23: =('Balance Sheet'!F39+'Balance Sheet'!F47)-('Balance Sheet'!E39+'Balance Sheet'!E47) -> 0 | G23: =('Balance Sheet'!G39+'Balance Sheet'!G47)-('Balance Sheet'!F39+'Balance Sheet'!F47) -> 0 | H23: =('Balance Sheet'!H39+'Balance Sheet'!H47)-('Balance Sheet'!G39+'Balance Sheet'!G47) -> 0 | I23: =('Balance Sheet'!I39+'Balance Sheet'!I47)-('Balance Sheet'!H39+'Balance Sheet'!H47) -> 0 | J23: =('Balance Sheet'!J39+'Balance Sheet'!J47)-('Balance Sheet'!I39+'Balance Sheet'!I47) -> 0
B24: Other Current Liabilities | C24: 2272 | D24: 4867 | E24: 5922 | F24: ='Balance Sheet'!F41-'Balance Sheet'!E41 -> 0 | G24: ='Balance Sheet'!G41-'Balance Sheet'!F41 -> 0 | H24: ='Balance Sheet'!H41-'Balance Sheet'!G41 -> 0 | I24: ='Balance Sheet'!I41-'Balance Sheet'!H41 -> 0 | J24: ='Balance Sheet'!J41-'Balance Sheet'!I41 -> 0
B25: Other Long-Term Liabilities | C25: 553 | D25: 749 | E25: -975 | F25: ='Balance Sheet'!F51-'Balance Sheet'!E51 -> 0 | G25: ='Balance Sheet'!G51-'Balance Sheet'!F51 -> 0 | H25: ='Balance Sheet'!H51-'Balance Sheet'!G51 -> 0 | I25: ='Balance Sheet'!I51-'Balance Sheet'!H51 -> 0 | J25: ='Balance Sheet'!J51-'Balance Sheet'!I51 -> 0
B27: Net Cash from Operating Activities | C27: =SUM(C6:C25) -> 87582 | D27: =SUM(D6:D25) -> 118548 | E27: =SUM(E6:E25) -> 136162 | F27: =F6+SUM(F11:F25) -> 148675.6 | G27: =G6+SUM(G11:G25) -> 167738.24 | H27: =H6+SUM(H11:H25) -> 186144.33 | I27: =I6+SUM(I11:I25) -> 203046.57 | J27: =J6+SUM(J11:J25) -> 221610.24
B29: Investing Activities:
B30: Additions to Property and Equipment | C30: -28107 | D30: -44477 | E30: -64551 | F30: =-'Income Statement'!F11*Assumptions!E19 -> -66853.105 | G30: =-'Income Statement'!G11*Assumptions!F19 -> -70991.631 | H30: =-'Income Statement'!H11*Assumptions!G19 -> -74186.254 | I30: =-'Income Statement'!I11*Assumptions!H19 -> -76255.66 | J30: =-'Income Statement'!J11*Assumptions!I19 -> -77420.677
B31: Acquisitions, Net | C31: -1670 | D31: -69132 | E31: -5978 | F31: 0 | G31: 0 | H31: 0 | I31: 0 | J31: 0
B32: Purchases of Investments | C32: -37651 | D32: -17732 | E32: -29775 | F32: =-'Income Statement'!F11*Assumptions!E21 -> -31834.812 | G32: =-'Income Statement'!G11*Assumptions!F21 -> -33721.025 | H32: =-'Income Statement'!H11*Assumptions!G21 -> -35140.857 | I32: =-'Income Statement'!I11*Assumptions!H21 -> -36009.617 | J32: =-'Income Statement'!J11*Assumptions!I21 -> -36433.26
B33: Maturities of Investments | C33: 33510 | D33: 24775 | E33: 16079 | F33: 0 | G33: 0 | H33: 0 | I33: 0 | J33: 0
B34: Sales of Investments | C34: 14354 | D34: 10894 | E34: 9309 | F34: 0 | G34: 0 | H34: 0 | I34: 0 | J34: 0
B35: Other, Net | C35: -3116 | D35: -1298 | E35: 2317 | F35: 0 | G35: 0 | H35: 0 | I35: 0 | J35: 0
B37: Net Cash Used in Investing Activities | C37: =SUM(C30:C35) -> -22680 | D37: =SUM(D30:D35) -> -96970 | E37: =SUM(E30:E35) -> -72599 | F37: =SUM(F30:F35) -> -98687.917 | G37: =SUM(G30:G35) -> -104712.66 | H37: =SUM(H30:H35) -> -109327.11 | I37: =SUM(I30:I35) -> -112265.28 | J37: =SUM(J30:J35) -> -113853.94
B39: Financing Activities:
B40: Short-Term Debt Issued/(Repaid), Net | C40: 0 | D40: 5250 | E40: -5746 | F40: 0 | G40: 0 | H40: 0 | I40: 0 | J40: 0
B41: Long-Term Debt Issued | C41: 0 | D41: 24395 | E41: 0 | F41: 0 | G41: 0 | H41: 0 | I41: 0 | J41: 0
B42: Long-Term Debt Repaid | C42: -2750 | D42: -29070 | E42: -3216 | F42: 0 | G42: 0 | H42: 0 | I42: 0 | J42: 0
B43: Common Stock Issued | C43: 1866 | D43: 2002 | E43: 2056 | F43: 0 | G43: 0 | H43: 0 | I43: 0 | J43: 0
B44: Share Repurchases | C44: -22245 | D44: -17254 | E44: -18420 | F44: 0 | G44: 0 | H44: 0 | I44: 0 | J44: 0
B45: Dividends Paid | C45: -19800 | D45: -21771 | E45: -24082 | F45: =E45*(1+Assumptions!E29) -> -26490.2 | G45: =F45*(1+Assumptions!F29) -> -29139.22 | H45: =G45*(1+Assumptions!G29) -> -31907.446 | I45: =H45*(1+Assumptions!H29) -> -34779.116 | J45: =I45*(1+Assumptions!I29) -> -37735.341
B46: Other, Net | C46: -1006 | D46: -1309 | E46: -2291 | F46: 0 | G46: 0 | H46: 0 | I46: 0 | J46: 0
B48: Net Cash Used in Financing Activities | C48: =SUM(C40:C46) -> -43935 | D48: =SUM(D40:D46) -> -37757 | E48: =SUM(E40:E46) -> -51699 | F48: =SUM(F40:F46) -> -26490.2 | G48: =SUM(G40:G46) -> -29139.22 | H48: =SUM(H40:H46) -> -31907.446 | I48: =SUM(I40:I46) -> -34779.116 | J48: =SUM(J40:J46) -> -37735.341
B50: FX Effect on Cash and Cash Equivalents | C50: -194 | D50: -210 | E50: 63 | F50: 0 | G50: 0 | H50: 0 | I50: 0 | J50: 0
B52: Net Change in Cash and Cash Equivalents | C52: =SUM(C27+C37+C48+C50) -> 20773 | D52: =SUM(D27+D37+D48+D50) -> -16389 | E52: =SUM(E27+E37+E48+E50) -> 11927 | F52: =F27+F37+F48+F50 -> 23497.486 | G52: =G27+G37+G48+G50 -> 33886.361 | H52: =H27+H37+H48+H50 -> 44909.774 | I52: =I27+I37+I48+I50 -> 56002.179 | J52: =J27+J37+J48+J50 -> 70020.962
...

Sheet Supporting Schedules
B2: Supporting Schedules
B4: PP&E Schedule
B5: PP&E Schedule | C5: FY2025A | D5: FY2026E | E5: FY2027E | F5: FY2028E | G5: FY2029E | H5: FY2030E
B6: Beginning PP&E | C6: ='Balance Sheet'!D21 -> 135591 | D6: ='Balance Sheet'!E21 -> 204966 | E6: ='Balance Sheet'!F21 -> 233617.33 | F6: ='Balance Sheet'!G21 -> 262013.98 | G6: ='Balance Sheet'!H21 -> 290126.67 | H6: ='Balance Sheet'!I21 -> 317239.79
B7: + CapEx | C7: =-'Cash Flow Statement'!E30 -> 64551 | D7: =-'Cash Flow Statement'!F30 -> 66853.105 | E7: =-'Cash Flow Statement'!G30 -> 70991.631 | F7: =-'Cash Flow Statement'!H30 -> 74186.254 | G7: =-'Cash Flow Statement'!I30 -> 76255.66 | H7: =-'Cash Flow Statement'!J30 -> 77420.677
B8: - Depreciation | C8: ='Cash Flow Statement'!E11 -> 34153 | D8: ='Cash Flow Statement'!F11 -> 38201.774 | E8: ='Cash Flow Statement'!G11 -> 42594.978 | F8: ='Cash Flow Statement'!H11 -> 46073.568 | G8: ='Cash Flow Statement'!I11 -> 49142.537 | H8: ='Cash Flow Statement'!J11 -> 52372.811
B9: + Other PP&E movements | C9: 38977 | D9: 0 | E9: 0 | F9: 0 | G9: 0 | H9: 0
B10: Ending PP&E | C10: =C6+C7-C8+C9 -> 204966 | D10: =D6+D7-D8+D9 -> 233617.33 | E10: =E6+E7-E8+E9 -> 262013.98 | F10: =F6+F7-F8+F9 -> 290126.67 | G10: =G6+G7-G8+G9 -> 317239.79 | H10: =H6+H7-H8+H9 -> 342287.66
B12: Working Capital Schedule
B14: Accounts Receivable | C14: FY2025A | D14: FY2026E | E14: FY2027E | F14: FY2028E | G14: FY2029E | H14: FY2030E
B15: Revenue | C15: ='Income Statement'!E11 -> 281724 | D15: ='Income Statement'!F11 -> 318348.12 | E15: ='Income Statement'!G11 -> 354958.15 | F15: ='Income Statement'!H11 -> 390453.97 | G15: ='Income Statement'!I11 -> 423642.56 | H15: ='Income Statement'!J11 -> 455415.75
B16: AR % Revenue | C16: ='Balance Sheet'!E14/C15 -> 0.24813292 | D16: =Assumptions!E24 -> 0.25 | E16: =Assumptions!F24 -> 0.25 | F16: =Assumptions!G24 -> 0.248 | G16: =Assumptions!H24 -> 0.245 | H16: =Assumptions!I24 -> 0.24
B17: Ending AR | C17: =C15*C16 -> 69905 | D17: =D15*D16 -> 79587.03 | E17: =E15*E16 -> 88739.538 | F17: =F15*F16 -> 96832.584 | G17: =G15*G16 -> 103792.43 | H17: =H15*H16 -> 109299.78
B19: Inventory | C19: FY2025A | D19: FY2026E | E19: FY2027E | F19: FY2028E | G19: FY2029E | H19: FY2030E
B20: Revenue | C20: ='Income Statement'!E11 -> 281724 | D20: ='Income Statement'!F11 -> 318348.12 | E20: ='Income Statement'!G11 -> 354958.15 | F20: ='Income Statement'!H11 -> 390453.97 | G20: ='Income Statement'!I11 -> 423642.56 | H20: ='Income Statement'!J11 -> 455415.75
B21: Inventory % Revenue | C21: ='Balance Sheet'!E15/C20 -> 0.0033294998 | D21: =Assumptions!E25 -> 0.003 | E21: =Assumptions!F25 -> 0.003 | F21: =Assumptions!G25 -> 0.003 | G21: =Assumptions!H25 -> 0.003 | H21: =Assumptions!I25 -> 0.003
B22: Ending Inventory | C22: =C20*C21 -> 938 | D22: =D20*D21 -> 955.04436 | E22: =E20*E21 -> 1064.8745 | F22: =F20*F21 -> 1171.3619 | G22: =G20*G21 -> 1270.9277 | H22: =H20*H21 -> 1366.2472
B24: Accounts Payable | C24: FY2025A | D24: FY2026E | E24: FY2027E | F24: FY2028E | G24: FY2029E | H24: FY2030E
B25: Revenue | C25: ='Income Statement'!E11 -> 281724 | D25: ='Income Statement'!F11 -> 318348.12 | E25: ='Income Statement'!G11 -> 354958.15 | F25: ='Income Statement'!H11 -> 390453.97 | G25: ='Income Statement'!I11 -> 423642.56 | H25: ='Income Statement'!J11 -> 455415.75
B26: AP % Revenue | C26: ='Balance Sheet'!E35/C25 -> 0.098408371 | D26: =Assumptions!E26 -> 0.1 | E26: =Assumptions!F26 -> 0.1 | F26: =Assumptions!G26 -> 0.098 | G26: =Assumptions!H26 -> 0.096 | H26: =Assumptions!I26 -> 0.095
B27: Ending AP | C27: =C25*C26 -> 27724 | D27: =D25*D26 -> 31834.812 | E27: =E25*E26 -> 35495.815 | F27: =F25*F26 -> 38264.489 | G27: =G25*G26 -> 40669.685 | H27: =H25*H26 -> 43264.496
B29: Net Working Capital | C29: =C17+C22-C27 -> 43119 | D29: =D17+D22-D27 -> 48707.262 | E29: =E17+E22-E27 -> 54308.598 | F29: =F17+F22-F27 -> 59739.457 | G29: =G17+G22-G27 -> 64393.669 | H29: =H17+H22-H27 -> 67401.531
B30: Change in Net Working Capital | D30: =D29-C29 -> 5588.2624 | E30: =E29-D29 -> 5601.3352 | F30: =F29-E29 -> 5430.8598 | G30: =G29-F29 -> 4654.2113 | H30: =H29-G29 -> 3007.8622
B32: Investment Schedule
B34: Short-term Investments | C34: FY2025A | D34: FY2026E | E34: FY2027E | F34: FY2028E | G34: FY2029E | H34: FY2030E
B35: Beginning Balance | C35: ='Balance Sheet'!D11 -> 57228 | D35: =C40 -> 64323 | E35: =D40 -> 96157.812 | F35: =E40 -> 129878.84 | G35: =F40 -> 165019.69 | H35: =G40 -> 201029.31
B36: + Purchases | C36: =-'Cash Flow Statement'!E32 -> 29775 | D36: =-'Cash Flow Statement'!F32 -> 31834.812 | E36: =-'Cash Flow Statement'!G32 -> 33721.025 | F36: =-'Cash Flow Statement'!H32 -> 35140.857 | G36: =-'Cash Flow Statement'!I32 -> 36009.617 | H36: =-'Cash Flow Statement'!J32 -> 36433.26
B37: - Maturities | C37: 16079 | D37: 0 | E37: 0 | F37: 0 | G37: 0 | H37: 0
B38: - Sales | C38: ='Cash Flow Statement'!E34 -> 9309 | D38: 0 | E38: 0 | F38: 0 | G38: 0 | H38: 0
B39: + Other Movements | C39: ='Balance Sheet'!E11-C35-C36+C37+C38 -> 2708 | D39: 0 | E39: 0 | F39: 0 | G39: 0 | H39: 0
B40: Ending Balance | C40: =C35+C36-C37-C38+C39 -> 64323 | D40: =D35+D36-D37-D38+D39 -> 96157.812 | E40: =E35+E36-E37-E38+E39 -> 129878.84 | F40: =F35+F36-F37-F38+F39 -> 165019.69 | G40: =G35+G36-G37-G38+G39 -> 201029.31 | H40: =H35+H36-H37-H38+H39 -> 237462.57
B42: Depreciation Schedule
B44: Depreciation | C44: =C42*C43 -> 0 | D44: =D42*D43 -> 0 | E44: =E42*E43 -> 0 | F44: =F42*F43 -> 0 | G44: =G42*G43 -> 0 | H44: =H42*H43 -> 0
B45: Revenue | C45: ='Income Statement'!E11 -> 281724 | D45: ='Income Statement'!F11 -> 318348.12 | E45: ='Income Statement'!G11 -> 354958.15 | F45: ='Income Statement'!H11 -> 390453.97 | G45: ='Income Statement'!I11 -> 423642.56 | H45: ='Income Statement'!J11 -> 455415.75
B46: Depreciation % Revenue | C46: ='Cash Flow Statement'!E11/C45 -> 0.12122858 | D46: =Assumptions!E20 -> 0.12 | E46: =Assumptions!F20 -> 0.12 | F46: =Assumptions!G20 -> 0.118 | G46: =Assumptions!H20 -> 0.116 | H46: =Assumptions!I20 -> 0.115
B47: Depreciation Expense | C47: =C45*C46 -> 34153 | D47: =D45*D46 -> 38201.774 | E47: =E45*E46 -> 42594.978 | F47: =F45*F46 -> 46073.568 | G47: =G45*G46 -> 49142.537 | H47: =H45*H46 -> 52372.811

Sheet DCF Valuation
B2: DCF Valuation
B4: Unlevered Free Cash Flow | I4: DCF Assumptions
B5: ($ in millions, except per-share data) | C5: FY2026E | D5: FY2027E | E5: FY2028E | F5: FY2029E | G5: FY2030E | I5: Risk-Free Rate % | J5: 0.0461
B6: Revenue | C6: ='Income Statement'!F11 -> 318348.12 | D6: ='Income Statement'!G11 -> 354958.15 | E6: ='Income Statement'!H11 -> 390453.97 | F6: ='Income Statement'!I11 -> 423642.56 | G6: ='Income Statement'!J11 -> 455415.75 | I6: Beta | J6: 1.1
B7: Revenue Growth % | C7: ='Income Statement'!F11/'Income Statement'!E11-1 -> 0.13 | D7: ='Income Statement'!G11/'Income Statement'!F11-1 -> 0.115 | E7: ='Income Statement'!H11/'Income Statement'!G11-1 -> 0.1 | F7: ='Income Statement'!I11/'Income Statement'!H11-1 -> 0.085 | G7: ='Income Statement'!J11/'Income Statement'!I11-1 -> 0.075 | I7: Equity Risk Premium % | J7: 0.048
I8: Cost of Equity % | J8: =J5+(J6*J7) -> 0.0989
B9: EBIT/Operating Income | C9: ='Income Statement'!F28 -> 146440.14 | D9: ='Income Statement'!G28 -> 164345.63 | E9: ='Income Statement'!H28 -> 182342 | F9: ='Income Statement'!I28 -> 198264.72 | G9: ='Income Statement'!J28 -> 214956.23
B10: EBIT Margin % | C10: ='Income Statement'!F28/'Income Statement'!F11 -> 0.46 | D10: ='Income Statement'!G28/'Income Statement'!G11 -> 0.463 | E10: ='Income Statement'!H28/'Income Statement'!H11 -> 0.467 | F10: ='Income Statement'!I28/'Income Statement'!I11 -> 0.468 | G10: ='Income Statement'!J28/'Income Statement'!J11 -> 0.472 | I10: Pre-tax Cost of Debt Assumption | J10: 0.049
I11: Tax Rate | J11: =Assumptions!E16 -> 0.18
B12: Taxes on EBIT | C12: ='Income Statement'!F28*Assumptions!E16 -> 26359.224 | D12: ='Income Statement'!G28*Assumptions!F16 -> 29582.213 | E12: ='Income Statement'!H28*Assumptions!G16 -> 32821.561 | F12: ='Income Statement'!I28*Assumptions!H16 -> 35687.649 | G12: ='Income Statement'!J28*Assumptions!I16 -> 38692.122 | I12: After-Tax Cost of Debt | J12: =J10*(1-J11) -> 0.04018
B14: Net Operating Profit After Tax | C14: =C9-C12 -> 120080.91 | D14: =D9-D12 -> 134763.41 | E14: =E9-E12 -> 149520.44 | F14: =F9-F12 -> 162577.07 | G14: =G9-G12 -> 176264.11 | I14: Market Value of Equity ($m) | J14: =J19*'Income Statement'!E44 -> 2939111.2
I15: Market Value of Debt ($m) | J15: ='Balance Sheet'!E36+'Balance Sheet'!E37+'Balance Sheet'!E46 -> 43151
B16: Depreciation & Amortization | C16: ='Cash Flow Statement'!F11 -> 38201.774 | D16: ='Cash Flow Statement'!G11 -> 42594.978 | E16: ='Cash Flow Statement'!H11 -> 46073.568 | F16: ='Cash Flow Statement'!I11 -> 49142.537 | G16: ='Cash Flow Statement'!J11 -> 52372.811 | I16: Total Capital ($m) | J16: =J14+J15 -> 2982262.2
B17: Capital Expenditures | C17: ='Cash Flow Statement'!F30 -> -66853.105 | D17: ='Cash Flow Statement'!G30 -> -70991.631 | E17: ='Cash Flow Statement'!H30 -> -74186.254 | F17: ='Cash Flow Statement'!I30 -> -76255.66 | G17: ='Cash Flow Statement'!J30 -> -77420.677 | I17: Weight of Equity | J17: =J14/J16 -> 0.98553078
B18: Change in Net Working Capital | C18: ='Supporting Schedules'!D30 -> 5588.2624 | D18: ='Supporting Schedules'!E30 -> 5601.3352 | E18: ='Supporting Schedules'!F30 -> 5430.8598 | F18: ='Supporting Schedules'!G30 -> 4654.2113 | G18: ='Supporting Schedules'!H30 -> 3007.8622 | I18: Weight of Debt | J18: =J15/J16 -> 0.014469217
I19: Current Share Price ($) | J19: 393.35
B20: Unlevered Free Cash Flow (UFCF) | C20: =C14+C16+C17-C18 -> 85841.318 | D20: =D14+D16+D17-D18 -> 100765.43 | E20: =E14+E16+E17-E18 -> 115976.9 | F20: =F14+F16+F17-F18 -> 130809.73 | G20: =G14+G16+G17-G18 -> 148208.38 | I20: Valuation Date | J20: 46231
I21: WACC | J21: =J17*J8+J18*J12 -> 0.098050368
B22: UFCF Growth % | D22: =D20/C20-1 -> 0.17385692 | E22: =E20/D20-1 -> 0.15095924 | F22: =F20/E20-1 -> 0.12789474 | G22: =G20/F20-1 -> 0.13300731 | I22: Terminal Growth Rate | J22: 0.025
B24: Present Value of UFCF | I24: Key Outputs
B25: ($ in millions) | C25: FY2026E | D25: FY2027E | E25: FY2028E | F25: FY2029E | G25: FY2030E | I25: Diluted Shares Outstanding (m) | J25: ='Income Statement'!E44 -> 7472
B26: Discount Period | C26: 1 | D26: 2 | E26: 3 | F26: 4 | G26: 5 | I26: Implied Share Price ($/share) | J26: =C60 -> 239.07195
B27: UFCF | C27: =C20 -> 85841.318 | D27: =D20 -> 100765.43 | E27: =E20 -> 115976.9 | F27: =F20 -> 130809.73 | G27: =G20 -> 148208.38 | I27: Current Share Price ($/share) | J27: =J19 -> 393.35
B28: Discount Factor @ WACC | C28: =1/(1+$J$21)^C26 -> 0.91070504 | D28: =1/(1+$J$21)^D26 -> 0.82938366 | E28: =1/(1+$J$21)^E26 -> 0.75532388 | F28: =1/(1+$J$21)^F26 -> 0.68787726 | G28: =1/(1+$J$21)^G26 -> 0.62645329 | I28: Upside/ (Downside) | J28: =C63 -> -0.39221571
B30: PV of UFCF | C30: =C27*C28 -> 78176.12 | D30: =D27*D28 -> 83573.197 | E30: =E27*E28 -> 87600.12 | F30: =F27*F28 -> 89981.041 | G30: =G27*G28 -> 92845.629
B32: Total PV of UFCF | C32: =SUM(C30:G30) -> 432176.11
B34: Terminal Value
B35: FY2030E UFCF | C35: =G20 -> 148208.38
B36: Terminal Growth Rate | C36: =J22 -> 0.025
B37: FY2031E UFCF | C37: =C35*(1+C36) -> 151913.59
B38: WACC | C38: =J21 -> 0.098050368
B40: Terminal Value | C40: =C37/(C38-C36) -> 2079573.3
B42: Discount Factor | C42: =G28 -> 0.62645329
B44: PV of Terminal Value | C44: =C40*C42 -> 1302755.5
B46: Valuation Summary
B47: ($ in millions, except per-share data)
B49: Total PV of UFCF | C49: =C32 -> 432176.11
B50: PV of Terminal Value | C50: =C44 -> 1302755.5
B52: Enterprise Value | C52: =SUM(C49:C50) -> 1734931.6
B54: Cash and Short-Term Investments | C54: ='Balance Sheet'!E13 -> 94565
...

Sheet Sensitivity Analysis
B2: Sensitivity Analysis
B4: Implied Share Price Sensitivity ($/share)
B5: WACC ↓ / Terminal Growth → | C5: =$E$5-1% -> 0.015 | D5: =$E$5-0.5% -> 0.02 | E5: ='DCF Valuation'!$J$22 -> 0.025 | F5: =$E$5+0.5% -> 0.03 | G5: =$E$5+1% -> 0.035
B6: =$B$8-1% -> 0.088050368 | C6: =IF($B6<=C$5,"n/m",(SUMPRODUCT('DCF Valuation'!$C$27:$G$27,1/(1+$B6)^'DCF Valuation'!$C$26:$G$26)+('DCF Valuation'!$G$27*(1+C$5)/($B6-C$5))/(1+$B6)^'DCF Valuation'!$G$26+'DCF Valuation'!$C$54-'DCF Valuation'!$C$55)/'DCF Valuation'!$C$59) -> 247.11148 | D6: =IF($B6<=D$5,"n/m",(SUMPRODUCT('DCF Valuation'!$C$27:$G$27,1/(1+$B6)^'DCF Valuation'!$C$26:$G$26)+('DCF Valuation'!$G$27*(1+D$5)/($B6-D$5))/(1+$B6)^'DCF Valuation'!$G$26+'DCF Valuation'!$C$54-'DCF Valuation'!$C$55)/'DCF Valuation'!$C$59) -> 261.34647 | E6: =IF($B6<=E$5,"n/m",(SUMPRODUCT('DCF Valuation'!$C$27:$G$27,1/(1+$B6)^'DCF Valuation'!$C$26:$G$26)+('DCF Valuation'!$G$27*(1+E$5)/($B6-E$5))/(1+$B6)^'DCF Valuation'!$G$26+'DCF Valuation'!$C$54-'DCF Valuation'!$C$55)/'DCF Valuation'!$C$59) -> 277.83917 | F6: =IF($B6<=F$5,"n/m",(SUMPRODUCT('DCF Valuation'!$C$27:$G$27,1/(1+$B6)^'DCF Valuation'!$C$26:$G$26)+('DCF Valuation'!$G$27*(1+F$5)/($B6-F$5))/(1+$B6)^'DCF Valuation'!$G$26+'DCF Valuation'!$C$54-'DCF Valuation'!$C$55)/'DCF Valuation'!$C$59) -> 297.17297 | G6: =IF($B6<=G$5,"n/m",(SUMPRODUCT('DCF Valuation'!$C$27:$G$27,1/(1+$B6)^'DCF Valuation'!$C$26:$G$26)+('DCF Valuation'!$G$27*(1+G$5)/($B6-G$5))/(1+$B6)^'DCF Valuation'!$G$26+'DCF Valuation'!$C$54-'DCF Valuation'!$C$55)/'DCF Valuation'!$C$59) -> 320.1512
B7: =$B$8-0.5% -> 0.093050368 | C7: =IF($B7<=C$5,"n/m",(SUMPRODUCT('DCF Valuation'!$C$27:$G$27,1/(1+$B7)^'DCF Valuation'!$C$26:$G$26)+('DCF Valuation'!$G$27*(1+C$5)/($B7-C$5))/(1+$B7)^'DCF Valuation'!$G$26+'DCF Valuation'!$C$54-'DCF Valuation'!$C$55)/'DCF Valuation'!$C$59) -> 230.8613 | D7: =IF($B7<=D$5,"n/m",(SUMPRODUCT('DCF Valuation'!$C$27:$G$27,1/(1+$B7)^'DCF Valuation'!$C$26:$G$26)+('DCF Valuation'!$G$27*(1+D$5)/($B7-D$5))/(1+$B7)^'DCF Valuation'!$G$26+'DCF Valuation'!$C$54-'DCF Valuation'!$C$55)/'DCF Valuation'!$C$59) -> 243.04692 | E7: =IF($B7<=E$5,"n/m",(SUMPRODUCT('DCF Valuation'!$C$27:$G$27,1/(1+$B7)^'DCF Valuation'!$C$26:$G$26)+('DCF Valuation'!$G$27*(1+E$5)/($B7-E$5))/(1+$B7)^'DCF Valuation'!$G$26+'DCF Valuation'!$C$54-'DCF Valuation'!$C$55)/'DCF Valuation'!$C$59) -> 257.02323 | F7: =IF($B7<=F$5,"n/m",(SUMPRODUCT('DCF Valuation'!$C$27:$G$27,1/(1+$B7)^'DCF Valuation'!$C$26:$G$26)+('DCF Valuation'!$G$27*(1+F$5)/($B7-F$5))/(1+$B7)^'DCF Valuation'!$G$26+'DCF Valuation'!$C$54-'DCF Valuation'!$C$55)/'DCF Valuation'!$C$59) -> 273.21622 | G7: =IF($B7<=G$5,"n/m",(SUMPRODUCT('DCF Valuation'!$C$27:$G$27,1/(1+$B7)^'DCF Valuation'!$C$26:$G$26)+('DCF Valuation'!$G$27*(1+G$5)/($B7-G$5))/(1+$B7)^'DCF Valuation'!$G$26+'DCF Valuation'!$C$54-'DCF Valuation'!$C$55)/'DCF Valuation'!$C$59) -> 292.19869
B8: ='DCF Valuation'!$J$21 -> 0.098050368 | C8: =IF($B8<=C$5,"n/m",(SUMPRODUCT('DCF Valuation'!$C$27:$G$27,1/(1+$B8)^'DCF Valuation'!$C$26:$G$26)+('DCF Valuation'!$G$27*(1+C$5)/($B8-C$5))/(1+$B8)^'DCF Valuation'!$G$26+'DCF Valuation'!$C$54-'DCF Valuation'!$C$55)/'DCF Valuation'!$C$59) -> 216.58229 | D8: =IF($B8<=D$5,"n/m",(SUMPRODUCT('DCF Valuation'!$C$27:$G$27,1/(1+$B8)^'DCF Valuation'!$C$26:$G$26)+('DCF Valuation'!$G$27*(1+D$5)/($B8-D$5))/(1+$B8)^'DCF Valuation'!$G$26+'DCF Valuation'!$C$54-'DCF Valuation'!$C$55)/'DCF Valuation'!$C$59) -> 227.10676 | E8: =IF($B8<=E$5,"n/m",(SUMPRODUCT('DCF Valuation'!$C$27:$G$27,1/(1+$B8)^'DCF Valuation'!$C$26:$G$26)+('DCF Valuation'!$G$27*(1+E$5)/($B8-E$5))/(1+$B8)^'DCF Valuation'!$G$26+'DCF Valuation'!$C$54-'DCF Valuation'!$C$55)/'DCF Valuation'!$C$59) -> 239.07195 | F8: =IF($B8<=F$5,"n/m",(SUMPRODUCT('DCF Valuation'!$C$27:$G$27,1/(1+$B8)^'DCF Valuation'!$C$26:$G$26)+('DCF Valuation'!$G$27*(1+F$5)/($B8-F$5))/(1+$B8)^'DCF Valuation'!$G$26+'DCF Valuation'!$C$54-'DCF Valuation'!$C$55)/'DCF Valuation'!$C$59) -> 252.79542 | G8: =IF($B8<=G$5,"n/m",(SUMPRODUCT('DCF Valuation'!$C$27:$G$27,1/(1+$B8)^'DCF Valuation'!$C$26:$G$26)+('DCF Valuation'!$G$27*(1+G$5)/($B8-G$5))/(1+$B8)^'DCF Valuation'!$G$26+'DCF Valuation'!$C$54-'DCF Valuation'!$C$55)/'DCF Valuation'!$C$59) -> 268.69548
B9: =$B$8+0.5% -> 0.10305037 | C9: =IF($B9<=C$5,"n/m",(SUMPRODUCT('DCF Valuation'!$C$27:$G$27,1/(1+$B9)^'DCF Valuation'!$C$26:$G$26)+('DCF Valuation'!$G$27*(1+C$5)/($B9-C$5))/(1+$B9)^'DCF Valuation'!$G$26+'DCF Valuation'!$C$54-'DCF Valuation'!$C$55)/'DCF Valuation'!$C$59) -> 203.93834 | D9: =IF($B9<=D$5,"n/m",(SUMPRODUCT('DCF Valuation'!$C$27:$G$27,1/(1+$B9)^'DCF Valuation'!$C$26:$G$26)+('DCF Valuation'!$G$27*(1+D$5)/($B9-D$5))/(1+$B9)^'DCF Valuation'!$G$26+'DCF Valuation'!$C$54-'DCF Valuation'!$C$55)/'DCF Valuation'!$C$59) -> 213.09952 | E9: =IF($B9<=E$5,"n/m",(SUMPRODUCT('DCF Valuation'!$C$27:$G$27,1/(1+$B9)^'DCF Valuation'!$C$26:$G$26)+('DCF Valuation'!$G$27*(1+E$5)/($B9-E$5))/(1+$B9)^'DCF Valuation'!$G$26+'DCF Valuation'!$C$54-'DCF Valuation'!$C$55)/'DCF Valuation'!$C$59) -> 223.43447 | F9: =IF($B9<=F$5,"n/m",(SUMPRODUCT('DCF Valuation'!$C$27:$G$27,1/(1+$B9)^'DCF Valuation'!$C$26:$G$26)+('DCF Valuation'!$G$27*(1+F$5)/($B9-F$5))/(1+$B9)^'DCF Valuation'!$G$26+'DCF Valuation'!$C$54-'DCF Valuation'!$C$55)/'DCF Valuation'!$C$59) -> 235.18418 | G9: =IF($B9<=G$5,"n/m",(SUMPRODUCT('DCF Valuation'!$C$27:$G$27,1/(1+$B9)^'DCF Valuation'!$C$26:$G$26)+('DCF Valuation'!$G$27*(1+G$5)/($B9-G$5))/(1+$B9)^'DCF Valuation'!$G$26+'DCF Valuation'!$C$54-'DCF Valuation'!$C$55)/'DCF Valuation'!$C$59) -> 248.66051
B10: =$B$8+1% -> 0.10805037 | C10: =IF($B10<=C$5,"n/m",(SUMPRODUCT('DCF Valuation'!$C$27:$G$27,1/(1+$B10)^'DCF Valuation'!$C$26:$G$26)+('DCF Valuation'!$G$27*(1+C$5)/($B10-C$5))/(1+$B10)^'DCF Valuation'!$G$26+'DCF Valuation'!$C$54-'DCF Valuation'!$C$55)/'DCF Valuation'!$C$59) -> 192.66556 | D10: =IF($B10<=D$5,"n/m",(SUMPRODUCT('DCF Valuation'!$C$27:$G$27,1/(1+$B10)^'DCF Valuation'!$C$26:$G$26)+('DCF Valuation'!$G$27*(1+D$5)/($B10-D$5))/(1+$B10)^'DCF Valuation'!$G$26+'DCF Valuation'!$C$54-'DCF Valuation'!$C$55)/'DCF Valuation'!$C$59) -> 200.69562 | E10: =IF($B10<=E$5,"n/m",(SUMPRODUCT('DCF Valuation'!$C$27:$G$27,1/(1+$B10)^'DCF Valuation'!$C$26:$G$26)+('DCF Valuation'!$G$27*(1+E$5)/($B10-E$5))/(1+$B10)^'DCF Valuation'!$G$26+'DCF Valuation'!$C$54-'DCF Valuation'!$C$55)/'DCF Valuation'!$C$59) -> 209.69257 | F10: =IF($B10<=F$5,"n/m",(SUMPRODUCT('DCF Valuation'!$C$27:$G$27,1/(1+$B10)^'DCF Valuation'!$C$26:$G$26)+('DCF Valuation'!$G$27*(1+F$5)/($B10-F$5))/(1+$B10)^'DCF Valuation'!$G$26+'DCF Valuation'!$C$54-'DCF Valuation'!$C$55)/'DCF Valuation'!$C$59) -> 219.84222 | G10: =IF($B10<=G$5,"n/m",(SUMPRODUCT('DCF Valuation'!$C$27:$G$27,1/(1+$B10)^'DCF Valuation'!$C$26:$G$26)+('DCF Valuation'!$G$27*(1+G$5)/($B10-G$5))/(1+$B10)^'DCF Valuation'!$G$26+'DCF Valuation'!$C$54-'DCF Valuation'!$C$55)/'DCF Valuation'!$C$59) -> 231.38129
B13: Base Case
B14: WACC | C14: ='DCF Valuation'!$J$21 -> 0.098050368
B15: Terminal Growth Rate | C15: ='DCF Valuation'!$J$22 -> 0.025
B16: Implied Share Price | C16: ='DCF Valuation'!$J$26 -> 239.07195
B17: Current Share Price | C17: ='DCF Valuation'!$J$27 -> 393.35
B18: Upside / (Downside) | C18: ='DCF Valuation'!$J$28 -> -0.39221571
